<?xml version='1.0'?>

<robot name="doug_bot" xmlns:xacro="http://www.ros.org/wiki/xacro">

  <xacro:property name="chassisradius"   value="0.2" />
  <xacro:property name="chassislength"   value="0.5" />
  <xacro:property name="chassispose"     value="0.0 0.0 0.06 0.0 0.0 0.0" />
  <xacro:property name="chassisorigin"   value="0.0 0.0 0.06" />

  <xacro:property name="wheelradius"     value="0.1" />
  <xacro:property name="wheellength"     value="0.05" />
  <xacro:property name="leftwheelpose"   value="0.0  0.0 0.0" />
  <xacro:property name="rightwheelpose"  value="0.0  0.0 0.0" />
  <xacro:property name="leftwheelhinge"  value="0.0  0.225 -0.15" />
  <xacro:property name="rightwheelhinge" value="0.0 -0.225 -0.15" />
 
  <xacro:property name="casterradius"    value="0.05" />
  <xacro:property name="frontcasterpose" value="0.125 0.0 -0.2" />
  <xacro:property name="backcasterpose"  value="-0.125 0.0 -0.2" />

  <xacro:property name="domeradius"      value="0.2" />
  <xacro:property name="domepose"        value="0.0 0.0 0.3" />

  <xacro:property name="camerasize"      value="0.05 0.05 0.05" />
  <xacro:property name="camerapose"      value="0.0 0.0 0.2" />

  <xacro:property name="hokuyopose"      value="0.0 0.0 0.25" />
  <xacro:property name="hokuyojoint"     value="0.0 0.0 0.25" />

  <xacro:include filename="$(find doug_bot)/urdf/doug_bot.gazebo" />

  <material name="blue">
    <color rgba="0 0 0.8 1"/>
  </material>

  <material name="turquoise">
    <color rgba="0.25 0.88 0.82 1"/>
  </material>

  <material name="yellow">
    <color rgba="0.8 0.8 0 1"/>
  </material>

  <material name="purple">
    <color rgba="0.8 0 0.8 1"/>
  </material>

  <material name="green">
    <color rgba="0 0.8 0 1"/>
  </material>

  <material name="black">
    <color rgba="0 0 0 1"/>
  </material>

  <material name="white">
    <color rgba="1 1 1 1"/>
  </material>

  <link name="robot_footprint"></link>

  <joint name="robot_footprint_joint" type="fixed">
    <origin xyz="0 0 0" rpy="0 0 0" />
    <parent link="robot_footprint"/>
    <child link="chassis" />
  </joint>

  <link name='chassis'>
    <pose>${chassispose}</pose>

    <inertial>
      <mass value="15.0"/>
      <origin xyz="0.0 0.0 0.0" rpy=" 0 0 0"/>
      <inertia
          ixx="0.1" ixy="0" ixz="0"
          iyy="0.1" iyz="0"
          izz="0.1"
      />
    </inertial>

    <collision name='collision'>
      <origin xyz="${chassisorigin}" rpy=" 0 0 ${pi/4}"/> 
      <geometry>
        <cylinder radius="${chassisradius}" length="${chassislength}"/>
      </geometry>
    </collision>

    <visual name='chassis_visual'>
      <origin xyz="${chassisorigin}" rpy="0 0 ${pi/4}"/>
      <geometry>
        <cylinder radius="${chassisradius}" length="${chassislength}"/>
      </geometry>
      <material name="blue"/>
   </visual>


    <collision name='back_caster_collision'>
      <origin xyz="${backcasterpose}" rpy=" 0 0 0"/>
      <geometry>
        <sphere radius="${casterradius}"/>
      </geometry>
      <surface>
        <friction>
          <ode>
            <mu>0</mu>
            <mu2>0</mu2>
            <slip1>1.0</slip1>
            <slip2>1.0</slip2>
          </ode>
        </friction>
      </surface>
    </collision>

    <visual name='back_caster_visual'>
      <origin xyz="${backcasterpose}" rpy=" 0 0 0"/>
      <geometry>
        <sphere radius="${casterradius}"/>
      </geometry>
    </visual>

    <collision name='front_caster_collision'>
      <origin xyz="${frontcasterpose}" rpy=" 0 0 0"/>
      <geometry>
        <sphere radius="${casterradius}"/>
      </geometry>
      <surface>
        <friction>
          <ode>
            <mu>0</mu>
            <mu2>0</mu2>
            <slip1>1.0</slip1>
            <slip2>1.0</slip2>
          </ode>
        </friction>
      </surface>
    </collision>

    <visual name='front_caster_visual'>
      <origin xyz="${frontcasterpose}" rpy=" 0 0 0"/>
      <geometry>
        <sphere radius="${casterradius}"/>
      </geometry>
    </visual>

    <collision name='dome_collision'>
      <origin xyz="${domepose}" rpy=" 0 0 0"/>
      <geometry>
        <sphere radius="${domeradius}"/>
      </geometry>
    </collision>

    <visual name='dome_visual'>
      <origin xyz="${domepose}" rpy=" 0 0 0"/>
      <geometry>
        <sphere radius="${domeradius}"/>
      </geometry>
      <material name="blue"/>
    </visual>

  </link>

  <link name="left_wheel">
    <collision name='left_wheel_collision'>
      <origin xyz="${leftwheelpose}" rpy=" 0.0 ${pi/2} ${pi/2}"/>
      <geometry>
        <cylinder radius="${wheelradius}" length="${wheellength}"/>
      </geometry>
      <surface>
        <friction>
          <ode>
            <mu>0</mu>
            <mu2>0</mu2>
            <slip1>1.0</slip1>
            <slip2>1.0</slip2>
          </ode>
        </friction>
      </surface>
    </collision>
    <inertial>
      <mass value="5.0"/>
      <origin xyz="0.0 0 0" rpy=" 0 0 0"/>
      <inertia
          ixx="0.1" ixy="0" ixz="0"
          iyy="0.1" iyz="0"
          izz="0.1"
      />
    </inertial>
    <visual name='left_wheel_visual'>
     <origin xyz="${leftwheelpose}" rpy=" 0.0 ${pi/2} ${pi/2}"/>
      <geometry>
        <cylinder radius="${wheelradius}" length="${wheellength}"/>
      </geometry>
       <material name="purple"/>
   </visual>
  </link>

  <joint type="continuous" name="left_wheel_hinge">
    <origin xyz="${leftwheelhinge}" rpy="0 0 0"/>
    <child link="left_wheel"/>
    <parent link="chassis"/>
    <axis xyz="0 1 0" rpy="0 0 0"/>
    <limit effort="10000" velocity="1000"/>
    <joint_properties damping="1.0" friction="1.0"/>
  </joint>

  <link name="right_wheel">
    <collision name='right_wheel_collision'>
      <origin xyz="${rightwheelpose}" rpy=" 0.0 ${pi/2} ${pi/2}"/>
      <geometry>
        <cylinder radius="${wheelradius}" length="${wheellength}"/>
      </geometry>
      <surface>
        <friction>
          <ode>
            <mu>0</mu>
            <mu2>0</mu2>
            <slip1>1.0</slip1>
            <slip2>1.0</slip2>
          </ode>
        </friction>
      </surface>
    </collision>
    <inertial>
      <mass value="5.0"/>
      <origin xyz="0.0 0.0 0.0" rpy=" 0.0 0.0 0.0"/>
      <inertia
          ixx="0.1" ixy="0" ixz="0"
          iyy="0.1" iyz="0"
          izz="0.1"
      />
    </inertial>
    <visual name='right_wheel_visual'>
      <origin xyz="${rightwheelpose}" rpy=" 0.0 ${pi/2} ${pi/2}"/>
      <geometry>
        <cylinder radius="${wheelradius}" length="${wheellength}"/>
      </geometry>
      <material name="purple"/>
    </visual>
  </link>
  <joint type="continuous" name="right_wheel_hinge">
    <origin xyz="${rightwheelhinge}" rpy="0 0 0"/>
    <child link="right_wheel"/>
    <parent link="chassis"/>
    <axis xyz="0 1 0" rpy="0 0 0"/>
    <limit effort="10000" velocity="1000"/>
    <joint_properties damping="1.0" friction="1.0"/>
  </joint>

  <link name="camera">
    <collision name='camera_collision'>
      <origin xyz="${camerapose}" rpy=" 0.0 0.0 0.0"/>
      <geometry>
        <box size="${camerasize}"/>
      </geometry>
      <surface>
        <friction>
          <ode>
            <mu>0</mu>
            <mu2>0</mu2>
            <slip1>1.0</slip1>
            <slip2>1.0</slip2>
          </ode>
        </friction>
      </surface>
    </collision>
    <inertial>
      <mass value="0.1"/>
      <origin xyz="0.0 0.0 0.0" rpy=" 0.0 0.0 0.0"/>
      <inertia
          ixx="1e-6" ixy="0" ixz="0"
          iyy="1e-6" iyz="0"
          izz="1e-6"
      />
    </inertial>
    <visual name='camera_visual'>
      <origin xyz="${camerapose}" rpy=" 0.0 0.0 0.0"/>
      <geometry>
        <box size="${camerasize}"/>
      </geometry>
      <material name="turquoise"/>
   </visual>
  </link>
  <joint type="continuous" name="camera_joint">
    <origin xyz="0.2 0.0 0.0" rpy="0 0 0"/>
    <child link="camera"/>
    <parent link="chassis"/>
    <axis xyz="0 1 0" rpy="0 0 0"/>
    <limit effort="10000" velocity="1000"/>
    <joint_properties damping="1.0" friction="1.0"/>
  </joint>

  <link name="hokuyo">
    <collision name='hokuyo_collision'>
      <origin xyz="${hokuyopose}" rpy=" 0.0 0.0 0.0"/>
      <geometry>
        <box size="0.1 0.1 0.1"/>
      </geometry>
      <surface>
        <friction>
          <ode>
            <mu>0</mu>
            <mu2>0</mu2>
            <slip1>1.0</slip1>
            <slip2>1.0</slip2>
          </ode>
        </friction>
      </surface>
    </collision>
    <inertial>
      <mass value="0.1"/>
      <origin xyz="0.0 0.0 0.0" rpy=" 0.0 0.0 0.0"/>
      <inertia
          ixx="1e-6" ixy="0" ixz="0"
          iyy="1e-6" iyz="0"
          izz="1e-6"
      />
    </inertial>
    <visual name='hokuyo_visual'>
      <origin xyz="${hokuyopose}" rpy=" 0.0 0.0 0.0"/>
      <geometry>
        <mesh filename="package://doug_bot/meshes/hokuyo.dae"/>
      </geometry>
   </visual>
  </link>
  <joint type="continuous" name="hokuyo_joint">
    <origin xyz="${hokuyojoint}" rpy="0 0 0"/>
    <child link="hokuyo"/>
    <parent link="chassis"/>
    <axis xyz="0 1 0" rpy="0 0 0"/>
    <limit effort="10000" velocity="1000"/>
    <joint_properties damping="1.0" friction="1.0"/>
  </joint>

</robot>
